<?xml version="1.0"?>
<robot name="omnibot_manipulator" xmlns:xacro="http://www.ros.org/wiki/xacro">

	<arg name="standalone_load" default="true" />

	<arg name="robot_namespace" default="omnibot_manipulator" />
	<xacro:property name="ns" value="$(arg robot_namespace)" />
	<xacro:unless value="${ns == '/' or ns != 'omnibot_manipulator'}">
		<gazebo>
			<plugin name="gazebo_ros_control" filename="libgazebo_ros_control.so">
				<robotNamespace>${ns}</robotNamespace>
			</plugin>
		</gazebo>
	</xacro:unless>

	<xacro:include
		filename="$(find omnibot_manipulator_description)/urdf/omnibot_manipulator.gazebo" />

	<xacro:property name="link_1_mesh_file_path"
		value="package://omnibot_manipulator_description/meshes/link1.dae" />
	<xacro:property name="link_2_mesh_file_path"
		value="package://omnibot_manipulator_description/meshes/link2.dae" />
	<xacro:property name="link_3_mesh_file_path"
		value="package://omnibot_manipulator_description/meshes/link3.dae" />
	<xacro:property name="link_4_mesh_file_path"
		value="package://omnibot_manipulator_description/meshes/link4.dae" />
	<xacro:property name="link_5_mesh_file_path"
		value="package://omnibot_manipulator_description/meshes/link5.dae" />
	<xacro:property name="link_6_mesh_file_path"
		value="package://omnibot_manipulator_description/meshes/link6.dae" />
	<xacro:property name="link_7_mesh_file_path"
		value="package://omnibot_manipulator_description/meshes/link7.dae" />


	<xacro:property name="joint_1_upper_limit" value="3.14" />
	<xacro:property name="joint_1_lower_limit" value="-3.14" />

	<xacro:property name="joint_2_upper_limit" value="1.57" />
	<xacro:property name="joint_2_lower_limit" value="-1.57" />

	<xacro:property name="joint_3_upper_limit" value="1.57" />
	<xacro:property name="joint_3_lower_limit" value="-1.57" />

	<xacro:property name="joint_4_upper_limit" value="1.57" />
	<xacro:property name="joint_4_lower_limit" value="-1.57" />

	<xacro:property name="joint_5_upper_limit" value="2.60" />
	<xacro:property name="joint_5_lower_limit" value="-2.60" />


	<xacro:if value="$(arg standalone_load)">
		<link name="world" />
		<joint name="map2base" type="fixed">
			<parent link="world" />
			<child link="ang_link0" />
			<origin xyz="0.0 0.0 0.0" rpy="0.0 0.0 0.0" />
		</joint>

	</xacro:if>


	<link name="ang_link0">
		<visual>
			<geometry>
				<mesh filename="${link_1_mesh_file_path}"
					scale="0.001 0.001 0.001" />
			</geometry>
		</visual>
		<inertial>
			<origin xyz="0 0 0.5" rpy="0 0 0" />
			<mass value="0.5" />
			<inertia
				ixx="0.01" ixy="0.0" ixz="0.0"
				iyy="0.01" iyz="0.0"
				izz="0.01" />
		</inertial>
		<collision>
			<geometry>
				<mesh filename="${link_1_mesh_file_path}"
					scale="0.001 0.001 0.001" />
			</geometry>
		</collision>
	</link>

	<joint name="ang_joint1" type="revolute">
		<parent link="ang_link0" />
		<child link="ang_link1" />
		<origin xyz="0 0 0.107" rpy="1.57 0 -1.57" />
		<axis xyz="0 1 0" />
		<dynamics damping="0.99" />
		<limit upper="${joint_1_upper_limit}" lower="${joint_1_lower_limit}" effort="5.0"
			velocity="5.0" />
	</joint>

	<link name="ang_link1">
		<visual>
			<geometry>
				<mesh filename="${link_2_mesh_file_path}"
					scale="0.001 0.001 0.001" />
			</geometry>
		</visual>
		<inertial>
			<origin xyz="0 0.25 0" rpy="0 0 0" />
			<mass value="0.3" />
			<inertia
				ixx="0.01" ixy="0.0" ixz="0.0"
				iyy="0.01" iyz="0.0"
				izz="0.01" />
		</inertial>
		<collision>
			<geometry>
				<mesh filename="${link_2_mesh_file_path}"
					scale="0.001 0.001 0.001" />
			</geometry>
		</collision>
	</link>

	<joint name="ang_joint2" type="revolute">
		<parent link="ang_link1" />
		<child link="ang_link2" />
		<origin xyz="0 0.0518 0" rpy="0 0 0" />
		<axis xyz="0 0 1" />
		<dynamics damping="0.99" />
		<limit upper="${joint_2_upper_limit}" lower="${joint_2_lower_limit}" effort="5.0"
			velocity="5.0" />
	</joint>

	<link name="ang_link2">
		<visual>
			<geometry>
				<mesh filename="${link_3_mesh_file_path}" scale="0.001 0.001 0.001" />
			</geometry>
		</visual>
		<inertial>
			<origin xyz="0 0.15 0" rpy="0 0 0" />
			<mass value="0.3" />
			<inertia
				ixx="0.01" ixy="0.0" ixz="0.0"
				iyy="0.01" iyz="0.0"
				izz="0.01" />
		</inertial>
		<collision>
			<geometry>
				<mesh filename="${link_3_mesh_file_path}"
					scale="0.001 0.001 0.001" />
			</geometry>
		</collision>
	</link>

	<joint name="ang_joint3" type="revolute">
		<parent link="ang_link2" />
		<child link="ang_link3" />
		<origin xyz="0.0626 0.1989 0" rpy="0 0 0" />
		<axis xyz="0 0 1" />
		<dynamics damping="0.99" />
		<limit upper="${joint_3_upper_limit}" lower="${joint_3_lower_limit}" effort="5.0"
			velocity="5.0" />
	</joint>

	<link name="ang_link3">
		<visual>
			<geometry>
				<mesh filename="${link_4_mesh_file_path}"
					scale="0.001 0.001 0.001" />
			</geometry>
		</visual>
		<inertial>
			<origin xyz="0 0 0" rpy="0 0 0" />
			<mass value="0.3" />
			<inertia
				ixx="0.01" ixy="0.0" ixz="0.0"
				iyy="0.01" iyz="0.0"
				izz="0.01" />
		</inertial>
		<collision>
			<geometry>
				<mesh filename="${link_4_mesh_file_path}"
					scale="0.001 0.001 0.001" />
			</geometry>
		</collision>
	</link>

	<joint name="ang_joint4" type="revolute">
		<parent link="ang_link3" />
		<child link="ang_link4" />
		<origin xyz="0.13093 0 0" rpy="-1.57 0 1.57" />
		<axis xyz="0 -1 0" />
		<dynamics damping="0.99" />
		<limit upper="${joint_4_upper_limit}" lower="${joint_4_lower_limit}" effort="5.0"
			velocity="5.0" />
	</joint>

	<link name="ang_link4">
		<visual>
			<geometry>
				<mesh filename="${link_5_mesh_file_path}"
					scale="0.001 0.001 0.001" />
			</geometry>
		</visual>
		<inertial>
			<origin xyz="0 0 0" rpy="0 0 0" />
			<mass value="0.3" />
			<inertia
				ixx="0.01" ixy="0.0" ixz="0.0"
				iyy="0.01" iyz="0.0"
				izz="0.01" />
		</inertial>
		<collision>
			<geometry>
				<mesh filename="${link_5_mesh_file_path}"
					scale="0.001 0.001 0.001" />
			</geometry>
		</collision>
	</link>

	<joint name="ang_joint5" type="revolute">
		<parent link="ang_link4" />
		<child link="ang_link5" />
		<origin xyz="0 0 -0.06174" rpy="0 0 0" />
		<axis xyz="0 0 -1" />
		<dynamics damping="0.99" />
		<limit upper="${joint_5_upper_limit}" lower="${joint_5_lower_limit}" effort="5.0"
			velocity="5.0" />
	</joint>

	
	

	<link name="ang_link5">
		<visual>
			<geometry>
				<mesh filename="${link_6_mesh_file_path}"
					scale="0.001 0.001 0.001" />
			</geometry>
		</visual>
		<inertial>
			<origin xyz="0 0 0" rpy="0 0 0" />
			<mass value="0.3" />
			<inertia
				ixx="0.01" ixy="0.0" ixz="0.0"
				iyy="0.01" iyz="0.0"
				izz="0.01" />
		</inertial>
		<collision>
			<geometry>
				<mesh filename="${link_6_mesh_file_path}"
					scale="0.001 0.001 0.001" />
			</geometry>
		</collision>
	</link>

	<link name="tip_link"/>
	<joint name="tip_joint" type="fixed">
		<parent link="ang_link5"/>
		<child link="tip_link"/>
		<origin xyz="0.0 0.0 -0.118" rpy="0.0 0.0 0.0"/>
	</joint>
	

	<joint name="ang_gripper" type="prismatic">
		<parent link="ang_link5" />
		<child link="ang_link6" />
		<origin xyz="0 0 -0.0715" rpy="1.57 3.14 0" />
		<axis xyz="0 0 1" />
		<limit effort="3" lower="0" upper="0.025" velocity="0.05" />
		<dynamics damping="0.99" />
	</joint>

	<link name="ang_link6">
		<collision>
			<geometry>
				<mesh filename="${link_7_mesh_file_path}"
					scale="0.001 0.001 0.001" />
			</geometry>
		</collision>
		<visual>
			<geometry>
				<mesh filename="${link_7_mesh_file_path}"
					scale="0.001 0.001 0.001" />
			</geometry>
		</visual>
		<inertial>
			<origin xyz="0 0 0" rpy="0 0 0" />
			<mass value="0.3" />
			<inertia
				ixx="0.01" ixy="0.0" ixz="0.0"
				iyy="0.01" iyz="0.0"
				izz="0.01" />
		</inertial>
	</link>
	<joint name="ang_gripper_sub" type="prismatic">
		<parent link="ang_link5" />
		<child link="ang_link7" />
		<origin xyz="0 0 -0.0715" rpy="-1.57 0 0" />
		<axis xyz="0 0 1" />
		<limit effort="3" lower="0" upper="0.025" velocity="0.05" />
		<mimic joint="ang_gripper" multiplier="1" offset="0" />
		<dynamics damping="0.99" />
	</joint>
	<link name="ang_link7">
		<collision>
			<geometry>
				<mesh filename="${link_7_mesh_file_path}"
					scale="0.001 0.001 0.001" />
			</geometry>
		</collision>
		<visual>
			<geometry>
				<mesh filename="${link_7_mesh_file_path}"
					scale="0.001 0.001 0.001" />
			</geometry>
		</visual>
		<inertial>
			<origin xyz="0 0 0" rpy="0 0 0" />
			<mass value="0.1" />
			<inertia
				ixx="0.01" ixy="0.0" ixz="0.0"
				iyy="0.01" iyz="0.0"
				izz="0.01" />
		</inertial>
	</link>
</robot>