<?xml version="1.0" ?>
<robot name="mecanum_wheel" xmlns:xacro="http://ros.org/wiki/xacro">

  <xacro:include filename="wheel.xacro" />
  <xacro:include filename="rollers.xacro"  />

  <xacro:macro name="mecanum_wheel" params="name side interface *origin parent">  
    
    <xacro:wheel_link name="${name}" side="${side}" />    
    <xacro:rollers_link name="${name}" side="${side}" />

    <transmission name="${name}_mecanum_trans">
        <type>transmission_interface/SimpleTransmission</type>
        <actuator name="${name}_mecanum_motor">
            <mechanicalReduction>1</mechanicalReduction>
        </actuator>
        <joint name="${name}_mecanum_joint">
            <hardwareInterface>${interface}</hardwareInterface>
        </joint>
    </transmission>

    <joint name="${name}_mecanum_joint" type="continuous">
        <xacro:insert_block name="origin" />
        <parent link="${parent}" />
        <child link="${name}_mecanum_wheel_link" />
        <axis xyz="1 0 0" />
        <limit lower="-3.14" upper="3.14" effort="1000.0" velocity="100.0" />
    </joint>

    
    <gazebo>
      <plugin filename="gz-sim-joint-controller-system" name="gz::sim::systems::JointController">
                    <joint_name>${name}_mecanum_joint</joint_name>
                    <topic>${name}_mecanum_joint/velocity</topic>
                    <initial_velocity>0.0</initial_velocity>
      </plugin>
      <plugin  filename="gz-sim-joint-state-publisher-system" name="gz::sim::systems::JointStatePublisher">
          <joint_name>${name}_mecanum_joint</joint_name>
      </plugin>
    </gazebo>
  </xacro:macro>

</robot>