<?xml version="1.0"?>
<robot xmlns:xacro="http://www.ros.org/wiki/xacro" name="omniwheel">
    
    <xacro:property name="omniwheel_mesh_path" value="package://omnibot_platform_description/meshes/wheel.dae"/>
    <xacro:property name="omniwheel_mesh_scale_x" value="0.001"/>
    <xacro:property name="omniwheel_mesh_scale_y" value="0.001"/>
    <xacro:property name="omniwheel_mesh_scale_z" value="0.001"/>
    
    <xacro:macro name="omniwheel_macro" params="suffix *origin">

        <joint name="${suffix}_wheel_joint" type="revolute">
            <xacro:insert_block name="origin"/>
            <parent link="base_link"/>
            <child link="${suffix}_omniwheel_link"/>
            <axis xyz="0 1 0"/>
            <limit lower="-3.14" upper="3.14" effort="1000.0" velocity="50.0"/>
        </joint>


        <link name="${suffix}_omniwheel_link">
            <inertial>
                <origin xyz="0.0 0.0 0.0" rpy="0.0 0.0 0.0"/>
                <mass value="0.0"/>
                <inertia ixx="0.0" ixy="0.0" ixz="0.0" iyy="0.0" iyz="0.0" izz="0.0"/>
            </inertial>
            <visual name="">
                <origin xyz="0.0 0.0 0.0" rpy="0.0 0.0 0.0"/>
                <geometry>
                    <mesh filename="${omniwheel_mesh_path}" scale="${omniwheel_mesh_scale_x} ${omniwheel_mesh_scale_y} ${omniwheel_mesh_scale_z}"/>
                </geometry>
                <material name="">
                    <color rgba="1.0 0.0 0.0 1.0"/>
                    <texture filename=""/>
                </material>
            </visual>
            <collision>
            <origin xyz="0.0 0.0 0.0" rpy="0.0 0.0 0.0"/>
                <geometry>
                    <mesh filename="${omniwheel_mesh_path}" scale="${omniwheel_mesh_scale_x} ${omniwheel_mesh_scale_y} ${omniwheel_mesh_scale_z}"/>
                </geometry>
            </collision>
        </link>

       
    
    </xacro:macro>
    
</robot>