<?xml version="1.0" ?>
<!-- =================================================================================== -->
<!-- |    This document was autogenerated by xacro from omnibot_robot.urdf.xacro       | -->
<!-- |    EDITING THIS FILE BY HAND IS NOT RECOMMENDED                                 | -->
<!-- =================================================================================== -->
<robot name="omnibot_robot">
  <gazebo>
<<<<<<< HEAD
    <plugin filename="libgazebo_ros_control.so" name="gazebo_ros_control">
      <!-- <robotNamespace>/omnibot_robot</robotNamespace> -->
      <robotSimType>gazebo_ros_control/DefaultRobotHWSim</robotSimType>
=======
    <!-- <plugin name="gazebo_ros_control" filename="libgazebo_ros_planar_move.so"> -->
    <plugin filename="libgazebo_ros_control.so" name="gazebo_ros_control">
      <!-- <plugin name="differential_drive_controller" filename="libdiffdrive_plugin.so"> -->
      <!-- <robotNamespace>/omnibot_robot</robotNamespace> -->
      <robotSimType>gazebo_ros_control/DefaultRobotHWSim</robotSimType>
      <!-- <commandTopic>cmd_vel</commandTopic> -->
      <odometryTopic>odom</odometryTopic>
      <odometryFrame>odom</odometryFrame>
      <odometryRate>100.0</odometryRate>
      <robotBaseFrame>base_footprint</robotBaseFrame>
      <publishTF>false</publishTF>
>>>>>>> 539d3a378cd48d3556f85776a1d8884e9df79ef8
    </plugin>
  </gazebo>
  <!-- transmission -->
  <transmission name="ang_tran1">
    <type>transmission_interface/SimpleTransmission</type>
    <joint name="ang_joint1">
      <hardwareInterface>hardware_interface/EffortJointInterface</hardwareInterface>
    </joint>
    <actuator name="ang_motor1">
      <hardwareInterface>hardware_interface/EffortJointInterface</hardwareInterface>
      <mechanicalReduction>1</mechanicalReduction>
    </actuator>
  </transmission>
  <transmission name="ang_tran2">
    <type>transmission_interface/SimpleTransmission</type>
    <joint name="ang_joint2">
      <hardwareInterface>hardware_interface/EffortJointInterface</hardwareInterface>
    </joint>
    <actuator name="ang_motor2">
      <hardwareInterface>hardware_interface/EffortJointInterfacee</hardwareInterface>
      <mechanicalReduction>1</mechanicalReduction>
    </actuator>
  </transmission>
  <transmission name="ang_tran3">
    <type>transmission_interface/SimpleTransmission</type>
    <joint name="ang_joint3">
      <hardwareInterface>hardware_interface/EffortJointInterface</hardwareInterface>
    </joint>
    <actuator name="ang_motor3">
      <hardwareInterface>hardware_interface/EffortJointInterfacee</hardwareInterface>
      <mechanicalReduction>1</mechanicalReduction>
    </actuator>
  </transmission>
  <transmission name="ang_tran4">
    <type>transmission_interface/SimpleTransmission</type>
    <joint name="ang_joint4">
      <hardwareInterface>hardware_interface/EffortJointInterface</hardwareInterface>
    </joint>
    <actuator name="ang_motor4">
      <hardwareInterface>hardware_interface/EffortJointInterfacee</hardwareInterface>
      <mechanicalReduction>1</mechanicalReduction>
    </actuator>
  </transmission>
  <transmission name="ang_tran5">
    <type>transmission_interface/SimpleTransmission</type>
    <joint name="ang_joint5">
      <hardwareInterface>hardware_interface/EffortJointInterface</hardwareInterface>
    </joint>
    <actuator name="ang_motor5">
      <hardwareInterface>hardware_interface/EffortJointInterfacee</hardwareInterface>
      <mechanicalReduction>1</mechanicalReduction>
    </actuator>
  </transmission>
  <transmission name="ang_tran5">
    <type>transmission_interface/SimpleTransmission</type>
    <joint name="ang_gripper">
      <hardwareInterface>hardware_interface/EffortJointInterface</hardwareInterface>
    </joint>
    <actuator name="ang_motor5">
      <hardwareInterface>hardware_interface/EffortJointInterfacee</hardwareInterface>
      <mechanicalReduction>1</mechanicalReduction>
    </actuator>
  </transmission>
  <transmission name="ang_tran5">
    <type>transmission_interface/SimpleTransmission</type>
    <joint name="ang_gripper_sub">
      <hardwareInterface>hardware_interface/EffortJointInterface</hardwareInterface>
    </joint>
    <actuator name="ang_motor5">
      <hardwareInterface>hardware_interface/EffortJointInterfacee</hardwareInterface>
      <mechanicalReduction>1</mechanicalReduction>
    </actuator>
  </transmission>
  <gazebo reference="ang_link0">
    <material>Gazebo/Gray</material>
  </gazebo>
  <gazebo reference="ang_link1">
    <material>Gazebo/Gray</material>
  </gazebo>
  <gazebo reference="ang_link2">
    <material>Gazebo/Gray</material>
  </gazebo>
  <gazebo reference="ang_link3">
    <material>Gazebo/Gray</material>
  </gazebo>
  <gazebo reference="ang_link4">
    <material>Gazebo/Gray</material>
  </gazebo>
  <gazebo reference="ang_link5">
    <material>Gazebo/Gray</material>
  </gazebo>
  <gazebo reference="ang_link7">
    <material>Gazebo/Orange</material>
    <kp>10000.0</kp>
    <kd>10000.0</kd>
    <mu1>1000.0</mu1>
    <mu2>1000.0</mu2>
    <minDepth>0.001</minDepth>
    <maxVel>0</maxVel>
  </gazebo>
  <gazebo reference="ang_link6">
    <kp>10000.0</kp>
    <kd>10000.0</kd>
    <mu1>1000.0</mu1>
    <mu2>1000.0</mu2>
    <minDepth>0.001</minDepth>
    <maxVel>0</maxVel>
    <material>Gazebo/Orange</material>
  </gazebo>
  <link name="ang_link0">
    <visual>
      <geometry>
        <mesh filename="package://omnibot_manipulator/meshes/link1.dae" scale="0.001 0.001 0.001"/>
      </geometry>
    </visual>
    <collision>
      <geometry>
        <mesh filename="package://omnibot_manipulator/meshes/link1.dae" scale="0.001 0.001 0.001"/>
      </geometry>
    </collision>
    <inertial>
      <origin rpy="0 0 0" xyz="0 0 0.5"/>
      <mass value="1"/>
      <inertia ixx="0.01" ixy="0.0" ixz="0.0" iyy="0.01" iyz="0.0" izz="0.01"/>
    </inertial>
  </link>
  <joint name="ang_joint1" type="continuous">
    <parent link="ang_link0"/>
    <child link="ang_link1"/>
    <origin rpy="1.57 0 -1.57" xyz="0 0 0.107"/>
    <axis xyz="0 1 0"/>
    <dynamics damping="0.99"/>
    <limit effort="5.0" velocity="5.0"/>
  </joint>
  <link name="ang_link1">
    <visual>
      <geometry>
        <mesh filename="package://omnibot_manipulator/meshes/link2.dae" scale="0.001 0.001 0.001"/>
      </geometry>
    </visual>
    <collision>
      <geometry>
        <mesh filename="package://omnibot_manipulator/meshes/link2.dae" scale="0.001 0.001 0.001"/>
      </geometry>
    </collision>
    <inertial>
      <origin rpy="0 0 0" xyz="0 0.25 0"/>
      <mass value="0.001"/>
      <inertia ixx="0.01" ixy="0.0" ixz="0.0" iyy="0.01" iyz="0.0" izz="0.01"/>
    </inertial>
  </link>
  <joint name="ang_joint2" type="revolute">
    <parent link="ang_link1"/>
    <child link="ang_link2"/>
    <origin rpy="0 0 0" xyz="0 0.0518 0"/>
    <axis xyz="0 0 1"/>
    <dynamics damping="0.99"/>
    <limit effort="5.0" lower="-1.57" upper="1.57" velocity="5.0"/>
  </joint>
  <link name="ang_link2">
    <visual>
      <geometry>
        <mesh filename="package://omnibot_manipulator/meshes/link3.dae" scale="0.001 0.001 0.001"/>
      </geometry>
    </visual>
    <collision>
      <geometry>
        <mesh filename="package://omnibot_manipulator/meshes/link3.dae" scale="0.001 0.001 0.001"/>
      </geometry>
    </collision>
    <inertial>
      <origin rpy="0 0 0" xyz="0 0.15 0"/>
      <mass value="0.001"/>
      <inertia ixx="0.01" ixy="0.0" ixz="0.0" iyy="0.01" iyz="0.0" izz="0.01"/>
    </inertial>
  </link>
  <joint name="ang_joint3" type="revolute">
    <parent link="ang_link2"/>
    <child link="ang_link3"/>
    <origin rpy="0 0 0" xyz="0.0626 0.1989 0"/>
    <axis xyz="0 0 1"/>
    <dynamics damping="0.99"/>
    <limit effort="5.0" lower="-1.57" upper="1.57" velocity="5.0"/>
  </joint>
  <link name="ang_link3">
    <visual>
      <geometry>
        <mesh filename="package://omnibot_manipulator/meshes/link4.dae" scale="0.001 0.001 0.001"/>
      </geometry>
    </visual>
    <collision>
      <geometry>
        <mesh filename="package://omnibot_manipulator/meshes/link4.dae" scale="0.001 0.001 0.001"/>
      </geometry>
    </collision>
    <inertial>
      <origin rpy="0 0 0" xyz="0 0 0"/>
      <mass value="0.001"/>
      <inertia ixx="0.01" ixy="0.0" ixz="0.0" iyy="0.01" iyz="0.0" izz="0.01"/>
    </inertial>
  </link>
  <joint name="ang_joint4" type="revolute">
    <parent link="ang_link3"/>
    <child link="ang_link4"/>
    <origin rpy="-1.57 0 1.57" xyz="0.13093 0 0"/>
    <axis xyz="0 -1 0"/>
    <dynamics damping="0.99"/>
    <limit effort="5.0" lower="-1.45" upper="1.45" velocity="5.0"/>
  </joint>
  <link name="ang_link4">
    <visual>
      <geometry>
        <mesh filename="package://omnibot_manipulator/meshes/link5.dae" scale="0.001 0.001 0.001"/>
      </geometry>
    </visual>
    <collision>
      <geometry>
        <mesh filename="package://omnibot_manipulator/meshes/link5.dae" scale="0.001 0.001 0.001"/>
      </geometry>
    </collision>
    <inertial>
      <origin rpy="0 0 0" xyz="0 0 0"/>
      <mass value="0.001"/>
      <inertia ixx="0.01" ixy="0.0" ixz="0.0" iyy="0.01" iyz="0.0" izz="0.01"/>
    </inertial>
  </link>
  <joint name="ang_joint5" type="continuous">
    <parent link="ang_link4"/>
    <child link="ang_link5"/>
    <origin rpy="0 0 0" xyz="0 0 -0.06174"/>
    <axis xyz="0 0 -1"/>
    <dynamics damping="0.99"/>
    <limit effort="5.0" lower="-1.57" upper="1.57" velocity="5.0"/>
  </joint>
  <link name="ang_link5">
    <visual>
      <geometry>
        <mesh filename="package://omnibot_manipulator/meshes/link6.dae" scale="0.001 0.001 0.001"/>
      </geometry>
    </visual>
    <collision>
      <geometry>
        <mesh filename="package://omnibot_manipulator/meshes/link6.dae" scale="0.001 0.001 0.001"/>
      </geometry>
    </collision>
    <inertial>
      <origin rpy="0 0 0" xyz="0 0 0"/>
      <mass value="0.001"/>
      <inertia ixx="0.01" ixy="0.0" ixz="0.0" iyy="0.01" iyz="0.0" izz="0.01"/>
    </inertial>
  </link>
  <link name="tip_link">
    <inertial>
      <origin rpy="0 0 0" xyz="0 0.0 0"/>
      <mass value="0.00002"/>
      <inertia ixx="0.01" ixy="0.0" ixz="0.0" iyy="0.01" iyz="0.0" izz="0.01"/>
    </inertial>
  </link>
  <joint name="tip_joint" type="fixed">
    <origin rpy="0.0 0.0 0.0" xyz="0.0 0.0 -0.1"/>
    <parent link="ang_link5"/>
    <child link="tip_link"/>
    <axis xyz="0.0 0.0 0.0"/>
    <limit effort="0.0" lower="0.0" upper="0.0" velocity="0.0"/>
  </joint>
  <joint name="ang_gripper" type="prismatic">
    <parent link="tip_link"/>
    <child link="ang_link6"/>
    <origin rpy="1.57 3.14 0" xyz="0.0 0.0 0.0285"/>
    <axis xyz="0 0 1"/>
    <limit effort="3" lower="0" upper="0.025" velocity="0.05"/>
    <dynamics damping="0.99"/>
  </joint>
  <link name="ang_link6">
    <collision>
      <geometry>
        <mesh filename="package://omnibot_manipulator/meshes/link7.dae" scale="0.001 0.001 0.001"/>
      </geometry>
    </collision>
    <visual>
      <geometry>
        <mesh filename="package://omnibot_manipulator/meshes/link7.dae" scale="0.001 0.001 0.001"/>
      </geometry>
    </visual>
    <inertial>
      <origin rpy="0 0 0" xyz="0 0 0"/>
      <mass value="0.001"/>
      <inertia ixx="0.01" ixy="0.0" ixz="0.0" iyy="0.01" iyz="0.0" izz="0.01"/>
    </inertial>
  </link>
  <joint name="ang_gripper_sub" type="prismatic">
    <parent link="tip_link"/>
    <child link="ang_link7"/>
    <origin rpy="-1.57 0 0" xyz="0.0 0.0 0.0285"/>
    <axis xyz="0 0 1"/>
    <limit effort="3" lower="0" upper="0.025" velocity="0.05"/>
    <mimic joint="ang_gripper" multiplier="1" offset="0"/>
    <dynamics damping="0.99"/>
  </joint>
  <link name="ang_link7">
    <collision>
      <geometry>
        <mesh filename="package://omnibot_manipulator/meshes/link7.dae" scale="0.001 0.001 0.001"/>
      </geometry>
    </collision>
    <visual>
      <geometry>
        <mesh filename="package://omnibot_manipulator/meshes/link7.dae" scale="0.001 0.001 0.001"/>
      </geometry>
    </visual>
    <inertial>
      <origin rpy="0 0 0" xyz="0 0 0"/>
      <mass value="0.001"/>
      <inertia ixx="0.01" ixy="0.0" ixz="0.0" iyy="0.01" iyz="0.0" izz="0.01"/>
    </inertial>
  </link>
  <link name="base_link">
    <visual name="">
      <origin rpy="0.0 3.14 0.0" xyz="0.0 0.0 0.0"/>
      <geometry>
        <mesh filename="package://omnibot_platform/meshes/hodovaya_low.dae" scale="0.001 0.001 0.001"/>
      </geometry>
      <material name="">
        <color rgba="1.0 0.0 0.5 1.0"/>
        <texture filename=""/>
      </material>
    </visual>
    <collision>
      <origin rpy="0.0 3.14 0.0" xyz="0.0 0.0 0.0"/>
      <geometry>
        <mesh filename="package://omnibot_platform/meshes/hodovaya_low.dae" scale="0.001 0.001 0.001"/>
      </geometry>
    </collision>
    <inertial>
<<<<<<< HEAD
      <origin rpy="0 0 0" xyz="0 0.0 0"/>
      <mass value="3.0"/>
      <inertia ixx="1.0" ixy="1.0" ixz="1.0" iyy="0.01" iyz="0.0" izz="0.01"/>
=======
      <origin rpy="0.0 3.14 0.0" xyz="0.0 0.0 0.0"/>
      <mass value="5.0"/>
      <!-- <inertia ixx="${0.83*m*(y+z)}" ixy="0.0" ixz="0.0" iyy="${0.83*m*(x+z)}" iyz="0.0" izz="${0.83*m*(y+x)}" /> -->
      <inertia ixx="0.0" ixy="0.0" ixz="0.0" iyy="0.0" iyz="0.0" izz="0.0"/>
>>>>>>> 539d3a378cd48d3556f85776a1d8884e9df79ef8
    </inertial>
  </link>
  <link name="left_forward_wheel_link">
    <visual name="">
      <origin rpy="0.0 0.0 0.0" xyz="0.0 0.0 0.0"/>
      <geometry>
        <mesh filename="package://omnibot_platform/meshes/wheel_low.dae" scale="0.001 0.001 0.001"/>
      </geometry>
      <material name="">
        <color rgba="1.0 0.0 0.0 1.0"/>
        <texture filename=""/>
      </material>
    </visual>
    <collision>
      <origin rpy="0.0 0.0 0.0" xyz="0.0 0.0 0.0"/>
      <geometry>
        <mesh filename="package://omnibot_platform/meshes/wheel_low.dae" scale="0.001 0.001 0.001"/>
      </geometry>
    </collision>
    <inertial>
<<<<<<< HEAD
      <origin rpy="0 0 0" xyz="0 0.0 0"/>
      <mass value="0.2"/>
      <inertia ixx="0.01" ixy="0.0" ixz="0.0" iyy="0.01" iyz="0.0" izz="0.01"/>
=======
      <origin rpy="0.0 0.0 1.57" xyz="-0.15255 0.168 0.013285"/>
      <mass value="0.5"/>
      <!-- <inertia ixx="${m*(3*r*r+h*h)/12}" ixy="0" ixz="0" iyy="${m*(3*r*r+h*h)/12}" iyz="0" izz="${m*r*r/2}" /> -->
      <!-- <inertia ixx="0.012411765597" ixy="-0.000711733678" ixz="0.00050272983" iyy="0.015218160428" iyz="-0.000004273467" izz="0.011763977943" /> -->
      <!-- <inertia ixx="1e-10" ixy="0.0" ixz="1e-10" iyy="0.0" iyz="0.0" izz="1e-10"/> -->
      <inertia ixx="0.0" ixy="0.0" ixz="0.0" iyy="0.0" iyz="0.0" izz="0.0"/>
>>>>>>> 539d3a378cd48d3556f85776a1d8884e9df79ef8
    </inertial>
  </link>
  <gazebo reference="left_forward_wheel_link">
    <kp>10000.0</kp>
    <kd>10000.0</kd>
    <mu1>1000.0</mu1>
    <mu2>1000.0</mu2>
    <minDepth>0.001</minDepth>
    <maxVel>1.0</maxVel>
  </gazebo>
  <joint name="left_forward_wheel_joint" type="continuous">
    <origin rpy="0.0 0.0 1.57" xyz="-0.15255 0.168 0.013285"/>
    <parent link="base_link"/>
    <child link="left_forward_wheel_link"/>
    <axis xyz="0.0 1.0 0.0"/>
<<<<<<< HEAD
    <limit effort="0.0" velocity="0.0"/>
=======
    <limit effort="5.0" velocity="100000.0"/>
>>>>>>> 539d3a378cd48d3556f85776a1d8884e9df79ef8
  </joint>
  <transmission name="left_forward_wheel_transmission" type="SimpleTransmission">
    <type>transmission_interface/SimpleTransmission</type>
    <actuator name="left_forward_wheel_motor">
      <hardwareInterface>hardware_interface/VelocityJointInterface </hardwareInterface>
      <mechanicalReduction>1</mechanicalReduction>
    </actuator>
    <joint name="left_forward_wheel_joint">
      <hardwareInterface>hardware_interface/VelocityJointInterface</hardwareInterface>
    </joint>
  </transmission>
  <link name="right_forward_wheel_link">
    <visual name="">
      <origin rpy="0.0 0.0 0.0" xyz="0.0 0.0 0.0"/>
      <geometry>
        <mesh filename="package://omnibot_platform/meshes/wheel_low.dae" scale="0.001 0.001 0.001"/>
      </geometry>
      <material name="">
        <color rgba="1.0 0.0 0.0 1.0"/>
        <texture filename=""/>
      </material>
    </visual>
    <collision>
      <origin rpy="0.0 0.0 0.0" xyz="0.0 0.0 0.0"/>
      <geometry>
        <mesh filename="package://omnibot_platform/meshes/wheel_low.dae" scale="0.001 0.001 0.001"/>
      </geometry>
    </collision>
    <inertial>
<<<<<<< HEAD
      <origin rpy="0 0 0" xyz="0 0.0 0"/>
      <mass value="0.2"/>
      <inertia ixx="0.01" ixy="0.0" ixz="0.0" iyy="0.01" iyz="0.0" izz="0.01"/>
=======
      <origin rpy="0.0 0.0 -1.57" xyz="0.15255 0.168 0.013285"/>
      <mass value="0.5"/>
      <!-- <inertia ixx="${m*(3*r*r+h*h)/12}" ixy="0" ixz="0" iyy="${m*(3*r*r+h*h)/12}" iyz="0" izz="${m*r*r/2}" /> -->
      <!-- <inertia ixx="0.012411765597" ixy="-0.000711733678" ixz="0.00050272983" iyy="0.015218160428" iyz="-0.000004273467" izz="0.011763977943" /> -->
      <!-- <inertia ixx="1e-10" ixy="0.0" ixz="1e-10" iyy="0.0" iyz="0.0" izz="1e-10"/> -->
      <inertia ixx="0.0" ixy="0.0" ixz="0.0" iyy="0.0" iyz="0.0" izz="0.0"/>
>>>>>>> 539d3a378cd48d3556f85776a1d8884e9df79ef8
    </inertial>
  </link>
  <gazebo reference="right_forward_wheel_link">
    <kp>10000.0</kp>
    <kd>10000.0</kd>
    <mu1>1000.0</mu1>
    <mu2>1000.0</mu2>
    <minDepth>0.001</minDepth>
    <maxVel>1.0</maxVel>
  </gazebo>
  <joint name="right_forward_wheel_joint" type="continuous">
    <origin rpy="0.0 0.0 -1.57" xyz="0.15255 0.168 0.013285"/>
    <parent link="base_link"/>
    <child link="right_forward_wheel_link"/>
    <axis xyz="0.0 1.0 0.0"/>
<<<<<<< HEAD
    <limit effort="0.0" velocity="0.0"/>
=======
    <limit effort="5.0" velocity="100000.0"/>
>>>>>>> 539d3a378cd48d3556f85776a1d8884e9df79ef8
  </joint>
  <transmission name="right_forward_wheel_transmission" type="SimpleTransmission">
    <type>transmission_interface/SimpleTransmission</type>
    <actuator name="right_forward_wheel_motor">
      <hardwareInterface>hardware_interface/VelocityJointInterface </hardwareInterface>
      <mechanicalReduction>1</mechanicalReduction>
    </actuator>
    <joint name="right_forward_wheel_joint">
      <hardwareInterface>hardware_interface/VelocityJointInterface</hardwareInterface>
    </joint>
  </transmission>
  <link name="left_backward_wheel_link">
    <visual name="">
      <origin rpy="0.0 0.0 0.0" xyz="0.0 0.0 0.0"/>
      <geometry>
        <mesh filename="package://omnibot_platform/meshes/wheel_low.dae" scale="0.001 0.001 0.001"/>
      </geometry>
      <material name="">
        <color rgba="1.0 0.0 0.0 1.0"/>
        <texture filename=""/>
      </material>
    </visual>
    <collision>
      <origin rpy="0.0 0.0 0.0" xyz="0.0 0.0 0.0"/>
      <geometry>
        <mesh filename="package://omnibot_platform/meshes/wheel_low.dae" scale="0.001 0.001 0.001"/>
      </geometry>
    </collision>
    <inertial>
<<<<<<< HEAD
      <origin rpy="0 0 0" xyz="0 0.0 0"/>
      <mass value="0.2"/>
      <inertia ixx="0.01" ixy="0.0" ixz="0.0" iyy="0.01" iyz="0.0" izz="0.01"/>
=======
      <origin rpy="0.0 0.0  1.57" xyz="-0.15255 -0.168 0.013285"/>
      <mass value="0.5"/>
      <!-- <inertia ixx="${m*(3*r*r+h*h)/12}" ixy="0" ixz="0" iyy="${m*(3*r*r+h*h)/12}" iyz="0" izz="${m*r*r/2}" /> -->
      <!-- <inertia ixx="0.012411765597" ixy="-0.000711733678" ixz="0.00050272983" iyy="0.015218160428" iyz="-0.000004273467" izz="0.011763977943" /> -->
      <!-- <inertia ixx="1e-10" ixy="0.0" ixz="1e-10" iyy="0.0" iyz="0.0" izz="1e-10"/> -->
      <inertia ixx="0.0" ixy="0.0" ixz="0.0" iyy="0.0" iyz="0.0" izz="0.0"/>
>>>>>>> 539d3a378cd48d3556f85776a1d8884e9df79ef8
    </inertial>
  </link>
  <gazebo reference="left_backward_wheel_link">
    <kp>10000.0</kp>
    <kd>10000.0</kd>
    <mu1>1000.0</mu1>
    <mu2>1000.0</mu2>
    <minDepth>0.001</minDepth>
    <maxVel>1.0</maxVel>
  </gazebo>
  <joint name="left_backward_wheel_joint" type="continuous">
    <origin rpy="0.0 0.0  1.57" xyz="-0.15255 -0.168 0.013285"/>
    <parent link="base_link"/>
    <child link="left_backward_wheel_link"/>
    <axis xyz="0.0 1.0 0.0"/>
<<<<<<< HEAD
    <limit effort="0.0" velocity="0.0"/>
=======
    <limit effort="5.0" velocity="100000.0"/>
>>>>>>> 539d3a378cd48d3556f85776a1d8884e9df79ef8
  </joint>
  <transmission name="left_backward_wheel_transmission" type="SimpleTransmission">
    <type>transmission_interface/SimpleTransmission</type>
    <actuator name="left_backward_wheel_motor">
      <hardwareInterface>hardware_interface/VelocityJointInterface </hardwareInterface>
      <mechanicalReduction>1</mechanicalReduction>
    </actuator>
    <joint name="left_backward_wheel_joint">
      <hardwareInterface>hardware_interface/VelocityJointInterface</hardwareInterface>
    </joint>
  </transmission>
  <link name="right_backward_wheel_link">
    <visual name="">
      <origin rpy="0.0 0.0 0.0" xyz="0.0 0.0 0.0"/>
      <geometry>
        <mesh filename="package://omnibot_platform/meshes/wheel_low.dae" scale="0.001 0.001 0.001"/>
      </geometry>
      <material name="">
        <color rgba="1.0 0.0 0.0 1.0"/>
        <texture filename=""/>
      </material>
    </visual>
    <collision>
      <origin rpy="0.0 0.0 0.0" xyz="0.0 0.0 0.0"/>
      <geometry>
        <mesh filename="package://omnibot_platform/meshes/wheel_low.dae" scale="0.001 0.001 0.001"/>
      </geometry>
    </collision>
    <inertial>
<<<<<<< HEAD
      <origin rpy="0 0 0" xyz="0 0.0 0"/>
      <mass value="0.2"/>
      <inertia ixx="0.01" ixy="0.0" ixz="0.0" iyy="0.01" iyz="0.0" izz="0.01"/>
=======
      <origin rpy="0.0 0.0  -1.57" xyz="0.15255 -0.168 0.013285"/>
      <mass value="0.5"/>
      <!-- <inertia ixx="${m*(3*r*r+h*h)/12}" ixy="0" ixz="0" iyy="${m*(3*r*r+h*h)/12}" iyz="0" izz="${m*r*r/2}" /> -->
      <!-- <inertia ixx="0.012411765597" ixy="-0.000711733678" ixz="0.00050272983" iyy="0.015218160428" iyz="-0.000004273467" izz="0.011763977943" /> -->
      <!-- <inertia ixx="1e-10" ixy="0.0" ixz="1e-10" iyy="0.0" iyz="0.0" izz="1e-10"/> -->
      <inertia ixx="0.0" ixy="0.0" ixz="0.0" iyy="0.0" iyz="0.0" izz="0.0"/>
>>>>>>> 539d3a378cd48d3556f85776a1d8884e9df79ef8
    </inertial>
  </link>
  <gazebo reference="right_backward_wheel_link">
    <kp>10000.0</kp>
    <kd>10000.0</kd>
    <mu1>1000.0</mu1>
    <mu2>1000.0</mu2>
    <minDepth>0.001</minDepth>
    <maxVel>1.0</maxVel>
  </gazebo>
  <joint name="right_backward_wheel_joint" type="continuous">
    <origin rpy="0.0 0.0  -1.57" xyz="0.15255 -0.168 0.013285"/>
    <parent link="base_link"/>
    <child link="right_backward_wheel_link"/>
    <axis xyz="0.0 1.0 0.0"/>
<<<<<<< HEAD
    <limit effort="0.0" velocity="0.0"/>
=======
    <limit effort="5.0" velocity="100000.0"/>
>>>>>>> 539d3a378cd48d3556f85776a1d8884e9df79ef8
  </joint>
  <transmission name="right_backward_wheel_transmission" type="SimpleTransmission">
    <type>transmission_interface/SimpleTransmission</type>
    <actuator name="right_backward_wheel_motor">
      <hardwareInterface>hardware_interface/VelocityJointInterface </hardwareInterface>
      <mechanicalReduction>1</mechanicalReduction>
    </actuator>
    <joint name="right_backward_wheel_joint">
      <hardwareInterface>hardware_interface/VelocityJointInterface</hardwareInterface>
    </joint>
  </transmission>
  <joint name="manip2platform_connector" type="fixed">
    <parent link="base_link"/>
    <child link="ang_link0"/>
    <origin rpy="0.0 0.0 3.14" xyz="0.0 0.096 0.113"/>
  </joint>
</robot>

